test_purchase.py::FrontEndProductPurchaseTest::test_purchase_1
--------------------------------------------------------------------
Last Page: http://127.0.0.1:8081/
  Browser: chrome
Timestamp: 1639257233  (Unix Timestamp)
     Date: Saturday, December 11, 2021
     Time: 4:13:53 PM  (Eastern Daylight Time, UTC-05:00)
--------------------------------------------------------------------
Traceback: File "C:\Program Files\WindowsApps\PythonSoftwareFoundation.Python.3.9_3.9.2544.0_x64__qbz5n2kfra8p0\lib\unittest\case.py", line 592, in run
    self._callTestMethod(testMethod)
  File "C:\Program Files\WindowsApps\PythonSoftwareFoundation.Python.3.9_3.9.2544.0_x64__qbz5n2kfra8p0\lib\unittest\case.py", line 550, in _callTestMethod
    method()
  File "C:\Users\divay\Desktop\Assign6Final\CMPE327\qbay_test\frontend\test_purchase.py", line 91, in test_purchase_1
    self.click('input[id="'+self.uuid2+'"]')
  File "C:\Users\divay\AppData\Local\Packages\PythonSoftwareFoundation.Python.3.9_qbz5n2kfra8p0\LocalCache\local-packages\Python39\site-packages\seleniumbase\fixtures\base_case.py", line 229, in click
    element = page_actions.wait_for_element_visible(
  File "C:\Users\divay\AppData\Local\Packages\PythonSoftwareFoundation.Python.3.9_qbz5n2kfra8p0\LocalCache\local-packages\Python39\site-packages\seleniumbase\fixtures\page_actions.py", line 370, in wait_for_element_visible
    timeout_exception(NoSuchElementException, message)
  File "C:\Users\divay\AppData\Local\Packages\PythonSoftwareFoundation.Python.3.9_qbz5n2kfra8p0\LocalCache\local-packages\Python39\site-packages\seleniumbase\fixtures\page_actions.py", line 163, in timeout_exception
    raise exception(message)
Exception: Message: 
 Element {input[id="48e7441d-43fc-4378-bce4-641dcbdfbbb0"]} was not present after 6 seconds!
